Workbook

Sheet Top 200 COs
A1: MBN Selected? | B1: Selected? | C1: CLLI | D1: Site_Number | E1: Land_Ownership | F1: Asset_Type | G1: Primary_Use | H1: Secondary_Use | I1: LAT | J1: LONG | K1: Address | L1: City | M1: State | N1: Lease_ID | O1: REIT_ID | P1: Ownership | Q1: Entity_Name | R1: ABS_Category | S1: KOIOS - BSM 2025 | T1: KOIOS - UTILITIES 2025 | U1: KOIOS - BSM 2026 | V1: KOIOS - UTILITIES 2026 | W1: Square Ft-Interior | X1: Rack Count | Y1: KIN COPPER_SUBS | Z1: KIN FIBER_SUBS | AA1: KIN TOTAL_SUBS | AB1: Drop MRR | AC1: Drop MRR (Non OM) | AD1: Pass Through MRR | AE1: Drop MRR Total | AF1: COLO_MRR | AG1: Overall MRR Total | AH1: Min LEASE_ID - ExecutionDate | AI1: Site Photo Link | AJ1: Site Photo Link
C2: ABRDNCXA | D2: WNS1899 | E2: Owned | F2: Building | G2: Central Office | I2: 35.13472 | J2: -79.426783 | K2: 211 North Poplar Street | L2: Aberdeen | M2: NC | N2: ON017-NC-003 | O2: 204 | P2: REIT_ILEC | Q2: Windstream North Carolina| LLC | R2: ABS 2 | S2: 34426.06 | T2: 17596.95 | U2: 9988.85 | V2: 4668.77 | W2: 3604 | X2: 27 | Y2: 244 | Z2: 682 | AA2: 926 | AB2: 1470 | AC2: 14248.52 | AD2: 4304.8 | AE2: 15718.52 | AF2: 0 | AG2: 15718.52 | AI2: https://www.sitefotos.com/vpics/guestmapdev?w7t7y6 | AJ2: =HYPERLINK(AI2,"LINK") -> LINK
C3: ADELGAXA | D3: WNS1464 | E3: Owned | F3: Building | G3: Central Office | I3: 31.137892 | J3: -83.422447 | K3: 106 North Parrish Avenue | L3: Adel | M3: GA | N3: ON042-GA-002 | O3: 2354 | P3: REIT_ILEC | Q3: Windstream Georgia Communications| LLC | R3: ABS 1 | S3: 21133.02 | T3: 36863.82 | U3: 8916.16 | V3: 2275.09 | W3: 3331 | X3: 27 | Y3: 205 | Z3: 1371 | AA3: 1576 | AB3: 7641.5 | AC3: 11048.81 | AD3: 2320 | AE3: 18690.31 | AF3: 0 | AG3: 18690.31 | AH3: 42881 | AI3: https://sitefotos.com/vpics/guestmapdev?t8c7i4 | AJ3: =HYPERLINK(AI3,"LINK") -> LINK
C4: ANWOIAXO | D4: WNS0433 | E4: Owned | F4: Building | G4: Central Office | I4: 41.289147 | J4: -91.555145 | K4: 240 5th Street | L4: Ainsworth | M4: IA | N4: ON132-IA-1004 | O4: 3053 | P4: REIT_ILEC | Q4: Windstream Iowa Communications| Inc. | R4: ABS 2 | S4: 0 | T4: 0 | U4: 0 | V4: 0 | W4: 10084 | X4: 8 | Y4: 64 | Z4: 67 | AA4: 131 | AB4: 565 | AC4: 10064.1 | AD4: 19832.4 | AE4: 10629.1 | AF4: 0 | AG4: 10629.1 | AJ4: =HYPERLINK(AI4,"LINK") -> LINK
C5: ALCHFL01 | D5: WNS1425 | E5: Owned | F5: Building | G5: Central Office | H5: Warehouse | I5: 29.802351 | J5: -82.492208 | K5: 13715 West County Road 235 | L5: Alachua | M5: FL | N5: B047051 | O5: 2334 | P5: REIT_ILEC | Q5: Windstream Florida| Inc. | R5: ABS 2 | S5: 0 | T5: 0 | U5: 0 | V5: 0 | W5: 10685 | X5: 4 | Y5: 0 | Z5: 0 | AA5: 0 | AB5: 0 | AC5: 0 | AD5: 0 | AE5: 0 | AF5: 0 | AG5: 0 | AI5: https://www.google.com/maps/place/29%C2%B048'08.1%22N+82%C2%B029'32.7%22W/@29.8022512,-82.4930604,236m/data=!3m2!1e3!4b1!4m4!3m3!8m2!3d29.80225!4d-82.4924167?entry=ttu&amp;g_ep=EgoyMDI2MDIyNC4wIKXMDSoASAFQAw%3D%3D">Google Maps</a> | AJ5: =HYPERLINK(AI5,"LINK") -> LINK
C6: ALCHFLAJ | E6: Owned | F6: Building | G6: Central Office | I6: 29.789387 | J6: -82.495896 | K6: 14600 Main Street | L6: Alachua | M6: FL | N6: ON047-FL-1002 | O6: 2335 | P6: REIT_ILEC | Q6: Windstream Florida| Inc. | R6: ABS 2 | S6: 0 | T6: 0 | U6: 0 | V6: 0 | W6: 10685 | X6: #N/A | Y6: #N/A | Z6: #N/A | AA6: #N/A | AB6: #N/A | AC6: #N/A | AD6: #N/A | AE6: #N/A | AF6: #N/A | AG6: #N/A | AI6: https://www.google.com/maps/place/29%C2%B048'08.1%22N+82%C2%B029'32.7%22W/@29.8022512,-82.4930604,236m/data=!3m2!1e3!4b1!4m4!3m3!8m2!3d29.80225!4d-82.4924167?entry=ttu&amp;g_ep=EgoyMDI2MDIyNC4wIKXMDSoASAFQAw%3D%3D">Google Maps</a> | AJ6: =HYPERLINK(AI6,"LINK") -> LINK
C7: ALCHFLXA | D7: WNS1426 | E7: Owned | F7: Building | G7: Central Office | I7: 29.7894 | J7: -82.4962 | K7: 14600 Main St | L7: Alachua | M7: FL | N7: ON047-FL-003 | P7: WIN_ILEC | Q7: Windstream Florida| Inc. | R7: ABS 2 | S7: 46914.99 | T7: 21147.61 | U7: 6951.12 | V7: 14497.16 | W7: 3786 | X7: 32 | Y7: 385 | Z7: 769 | AA7: 1154 | AB7: 9195.43 | AC7: 14725.04 | AD7: 31318.52 | AE7: 23920.47 | AF7: 0 | AG7: 23920.47 | AH7: 43282 | AI7: https://www.google.com/maps/place/29%C2%B047'21.9%22N+82%C2%B029'45.1%22W/@29.7894179,-82.4965048,236m/data=!3m2!1e3!4b1!4m4!3m3!8m2!3d29.7894167!4d-82.4958611?entry=ttu&amp;g_ep=EgoyMDI2MDIyNC4wIKXMDSoASAFQAw%3D%3D">Google Maps</a> | AJ7: =HYPERLINK(AI7,"LINK") -> LINK
C8: ALBYKYXA | D8: WNS1699 | E8: Owned | F8: Building | G8: Central Office | I8: 36.693022 | J8: -85.134498 | K8: 400 N Washington | L8: Albany | M8: KY | N8: ON219-KY-001 | P8: WIN_ILEC | Q8: Windstream Kentucky East| LLC | R8: ABS 1 | S8: 12426.38 | T8: 39268.07 | U8: 845.98 | V8: 14894.06 | W8: 3680 | X8: 38 | Y8: 353 | Z8: 610 | AA8: 963 | AB8: 1940 | AC8: 21598.18 | AD8: 32660.33 | AE8: 23538.18 | AF8: 0 | AG8: 23538.18 | AI8: https://www.sitefotos.com/vpics/guestmapdev?h7c8f3 | AJ8: =HYPERLINK(AI8,"LINK") -> LINK
C9: ALBMNCXA | D9: WNS1901 | E9: Owned | F9: Building | G9: Central Office | H9: Tower | I9: 35.354042 | J9: -80.199092 | K9: 250 North 1st Street | L9: Albemarle | M9: NC | N9: B018200 | O9: 2508 | P9: REIT_ILEC | Q9: Windstream Concord Telephone| LLC | R9: ABS 2 | S9: 34465.89 | T9: 57466.96 | U9: 8877.62 | V9: 2845.28 | W9: 8000 | X9: 55 | Y9: 617 | Z9: 1991 | AA9: 2608 | AB9: 12968.9 | AC9: 17608.62 | AD9: 6325.38 | AE9: 30577.52 | AF9: 0 | AG9: 30577.52 | AH9: 41883 | AI9: https://www.sitefotos.com/vpics/guestmapdev?l2v3o8 | AJ9: =HYPERLINK(AI9,"LINK") -> LINK
C10: ALBIIAXO | D10: WNS0435 | E10: Owned | F10: Building | G10: Central Office | I10: 41.025959 | J10: -92.805646 | K10: 202 Washington Avenue E | L10: Albia | M10: IA | N10: ON132-IA-1009 | O10: 1643 | P10: REIT_ILEC | Q10: Windstream Iowa Communications| Inc. | R10: ABS 2 | S10: 4611.78 | T10: 8454.1 | U10: 1202.44 | V10: 2008.76 | W10: 4650 | X10: 13 | Y10: 469 | Z10: 269 | AA10: 738 | AB10: 860.5 | AC10: 6964.3 | AD10: 6047.8 | AE10: 7824.8 | AF10: 21 | AG10: 7845.8 | AI10: https://www.sitefotos.com/vpics/guestmapdev?c3k1y8 | AJ10: =HYPERLINK(AI10,"LINK") -> LINK
C11: ANDRTXXA | D11: WNS2514 | E11: Owned | F11: Building | G11: Central Office | I11: 32.317614 | J11: -102.54772 | K11: 112 Southwest 1st | L11: Andrews | M11: TX | N11: ON400-TX-012 | O11: 2824 | P11: REIT_ILEC | Q11: Valor Telecommunications of Texas| LLC | R11: ABS 1 | S11: 54750.84 | T11: 33972.51 | U11: 17661.46 | V11: 10902.59 | W11: 7280 | X11: 46 | Y11: 434 | Z11: 2113 | AA11: 2547 | AB11: 6552.65 | AC11: 15910.17 | AD11: 89613.87 | AE11: 22462.82 | AF11: 0 | AG11: 22462.82 | AI11: https://www.sitefotos.com/vpics/guestmapdev?r3x0w5 | AJ11: =HYPERLINK(AI11,"LINK") -> LINK
B12: Yes: 12k sqft + Owned | C12: ASLDKYXA | D12: WNS1701 | E12: Owned | F12: Building | G12: Central Office | I12: 38.4758 | J12: -82.64385 | K12: 619 15th Street | L12: Ashland | M12: KY | N12: B2193221111 | O12: 3469 | P12: REIT_ILEC | Q12: Windstream Kentucky East| LLC | R12: ABS 1 | S12: 80399.73 | T12: 247287.21 | U12: 15495.96 | V12: 97031.63 | W12: 34184 | X12: 232 | Y12: 223 | Z12: 1165 | AA12: 1388 | AB12: 23231.37 | AC12: 120711.48 | AD12: 101921.69 | AE12: 143942.85 | AF12: 0 | AG12: 143942.85 | AH12: 42881 | AI12: https://www.sitefotos.com/vpics/guestmapdev?c2k3m2 | AJ12: =HYPERLINK(AI12,"LINK") -> LINK
B13: Yes: 12k sqft + Owned | C13: MEDSKYXA | D13: WNS1703 | E13: Owned | F13: Building | G13: Central Office | I13: 38.40965 | J13: -82.713032 | K13: 9216 Highway 60 | L13: Ashland | M13: KY | N13: ON216-KY-002 | P13: WIN_ILEC | Q13: Windstream Kentucky East| LLC | R13: ABS 1 | S13: 56902.92 | T13: 87147.61 | U13: 18735.57 | V13: 34174.83 | W13: 12209 | X13: 76 | Y13: 281 | Z13: 1025 | AA13: 1306 | AB13: 16039.46 | AC13: 39822.17 | AD13: 92545.24 | AE13: 55861.63 | AF13: 0 | AG13: 55861.63 | AI13: https://www.sitefotos.com/vpics/guestmapdev?r3f5f4 | AJ13: =HYPERLINK(AI13,"LINK") -> LINK
C14: ADBNIAXO | D14: WNS1601 | E14: Owned | F14: Building | G14: Central Office | I14: 41.721272 | J14: -94.929383 | K14: 620 LEROY | L14: Audubon | M14: IA | N14: ON132-IA-1023 | O14: 2381 | P14: REIT_ILEC | Q14: Windstream Iowa Communications| Inc. | R14: ABS 2 | S14: 15615.69 | T14: 14045 | U14: 2820.67 | V14: 3549.97 | W14: 3744 | X14: 30 | Y14: 250 | Z14: 434 | AA14: 684 | AB14: 2819 | AC14: 6105.57 | AD14: 7682.1 | AE14: 8924.57 | AF14: 0 | AG14: 8924.57 | AI14: https://www.sitefotos.com/vpics/guestmapdev?u7n0l8 | AJ14: =HYPERLINK(AI14,"LINK") -> LINK
C15: AURROHXA | D15: WNS2239 | E15: Owned | F15: Building | G15: Central Office | I15: 41.317158 | J15: -81.346599 | K15: 27 East Garfield Road | L15: Aurora | M15: OH | N15: ON080-OH-001 | O15: 135 | P15: REIT_ILEC | Q15: Windstream Western Reserve| Inc. | R15: ABS 1 | S15: 50923.85 | T15: 58199.56 | U15: 22396.81 | V15: 12206.46 | W15: 5726 | X15: 70 | Y15: 391 | Z15: 288 | AA15: 679 | AB15: 12890.14 | AC15: 13102.87 | AD15: 44705.6 | AE15: 25993.01 | AF15: 0 | AG15: 25993.01 | AI15: https://www.sitefotos.com/vpics/guestmapdev?g8w0j7 | AJ15: =HYPERLINK(AI15,"LINK") -> LINK
B16: Yes: 12k sqft + Owned | C16: BNBGOHXA | D16: WNS1052 | E16: Owned | F16: Building | G16: Central Office | I16: 41.385699 | J16: -81.340629 | K16: 8425 Baindridge Road | L16: Bainbridge | M16: OH | N16: ON080-OH-003 | O16: 2020 | P16: REIT_ILEC | Q16: Windstream Western Reserve| Inc. | R16: ABS 1 | S16: 31055.14 | T16: 57971.48 | U16: 12785.38 | V16: 19898.04 | W16: 14355 | X16: 64 | Y16: 285 | Z16: 474 | AA16: 759 | AB16: 1021 | AC16: 7569.59 | AD16: 18040.8 | AE16: 8590.59 | AF16: 0 | AG16: 8590.59 | AI16: https://www.google.com/maps/place/8425+Bainbridge+Rd,+Chagrin+Falls,+OH+44023/@41.385724,-81.3409919,102m/data=!3m1!1e3!4m12!1m5!3m4!2zNDHCsDIzJzA4LjYiTiA4McKwMjAnMjYuNCJX!8m2!3d41.38572!4d-81.34067!3m5!1s0x88311a7811e73ce9:0x8ae504c98819a4a0!8m2!3d41.3857038!4d-81.3406819!16s%2Fg%2F11b8v5dgqb?entry=ttu&amp;g_ep=EgoyMDI1MTAwNy4wIKXMDSoASAFQAw%3D%3D">Google Maps</a> | AJ16: https://www.google.com/maps/place/8425+Bainbridge+Rd,+Chagrin+Falls,+OH+44023/@41.385724,-81.3409919,102m/data=!3m1!1e3!4m12!1m5!3m4!2zNDHCsDIzJzA4LjYiTiA4McKwMjAnMjYuNCJX!8m2!3d41.38572!4d-81.34067!3m5!1s0x88311a7811e73ce9:0x8ae504c98819a4a0!8m2!3d41.3857038!4d-81.3406819!16s%2Fg%2F11b8v5dgqb?entry=ttu&amp;g_ep=EgoyMDI1MTAwNy4wIKXMDSoASAFQAw%3D%3D">Google Maps</a>
B17: Yes: 12k sqft + Owned | C17: CRNLGA01 | D17: WNS0048 | E17: Owned | F17: Building | G17: Central Office | I17: 34.497208 | J17: -83.549978 | K17: 2000 Communications Boulevard | L17: Baldwin | M17: GA | N17: B040009 | O17: 3405 | P17: REIT_ILEC | Q17: Windstream Standard| LLC | R17: ABS 2 | S17: 0 | T17: 131239.21 | U17: 0 | V17: 35861.89 | W17: 55823 | X17: 11 | Y17: 541 | Z17: 0 | AA17: 541 | AB17: 0 | AC17: 0 | AD17: 1299 | AE17: 0 | AF17: 0 | AG17: 0 | AH17: 31383 | AI17: https://sitefotos.com/vpics/guestmapdev?g4t5f6 | AJ17: =HYPERLINK(AI17,"LINK") -> LINK
C18: BBVLKYXA | D18: WNS1705 | E18: Owned | F18: Building | G18: Central Office | I18: 36.865334 | J18: -83.888273 | K18: 207 South Main Street | L18: Barbourville | M18: KY | N18: ON220-KY-003 | O18: 191 | P18: REIT_ILEC | Q18: Windstream Kentucky East| LLC | R18: ABS 2 | S18: 18265.79 | T18: 34171.06 | U18: 7969.43 | V18: 9965.19 | W18: 3855 | X18: 28 | Y18: 237 | Z18: 405 | AA18: 642 | AB18: 6749 | AC18: 14920.37 | AD18: 47332.4 | AE18: 21669.37 | AF18: 0 | AG18: 21669.37 | AH18: 42767 | AI18: https://www.sitefotos.com/vpics/guestmapdev?j0l6w3 | AJ18: =HYPERLINK(AI18,"LINK") -> LINK
C19: FRVWOHXA | D19: WNS2241 | E19: Owned | F19: Building | G19: Central Office | I19: 40.059497 | J19: -81.220419 | K19: 32699 Old National Road | L19: Barnesville | M19: OH | N19: ON080-OH-041 | O19: 792 | P19: REIT_ILEC | Q19: Windstream Western Reserve| Inc. | R19: ABS 1 | S19: 17118.82 | T19: 21141.46 | U19: 9412.8 | V19: 11989.69 | W19: 3022 | X19: 28 | Y19: 113 | Z19: 0 | AA19: 113 | AB19: 1450 | AC19: 6356.9 | AD19: 46411.56 | AE19: 7806.9 | AF19: 0 | AG19: 7806.9 | AH19: 42767 | AI19: https://www.sitefotos.com/vpics/guestmapdev?x4v1m2 | AJ19: =HYPERLINK(AI19,"LINK") -> LINK
B20: Yes - High Rack count | C20: BEREKYXA | D20: WNS1709 | E20: Owned | F20: Building | G20: Central Office | H20: Switch | I20: 37.573344 | J20: -84.285739 | K20: 310 Center Street | L20: Berea | M20: KY | N20: ON219-KY-003 | O20: 227 | P20: REIT_ILEC | Q20: Windstream Kentucky East| LLC | R20: ABS 1 | S20: 17800.04 | T20: 51712.55 | U20: 4044.87 | V20: 16119.02 | W20: 3242 | X20: 90 | Y20: 166 | Z20: 846 | AA20: 1012 | AB20: 15989.08 | AC20: 57335.17 | AD20: 59842.41 | AE20: 73324.25 | AF20: 0 | AG20: 73324.25 | AH20: 42881 | AI20: https://www.sitefotos.com/vpics/guestmapdev?q6e1d4 | AJ20: =HYPERLINK(AI20,"LINK") -> LINK
C21: SHBGKYAB | E21: Owned | F21: Building | G21: Central Office | H21: Switch | I21: 38.242606 | J21: -83.874479 | K21: 160 Old Highway 11 | L21: BETHEL | M21: KY | N21: ON219-KY-060 | O21: 1306 | P21: REIT_ILEC | Q21: Windstream Kentucky East| LLC | R21: ABS 1 | S21: 0 | T21: 0 | U21: 0 | V21: 0 | W21: 10084 | X21: 3 | Y21: 41 | Z21: 85 | AA21: 126 | AB21: 0 | AC21: 295 | AD21: 0 | AE21: 295 | AF21: 0 | AG21: 295 | AI21: https://www.google.com/maps/place/4949+Summer+Shade+Rd,+Summer+Shade,+KY+42166/@36.8759171,-85.6601021,3a,37.5y,191.64h,87.75t/data=!3m7!1e1!3m5!1svrYjBVqy23or2j3c9KfHwQ!2e0!6shttps:%2F%2Fstreetviewpixels-pa.googleapis.com%2Fv1%2Fthumbnail%3Fcb_client%3Dmaps_sv.tactile%26w%3D900%26h%3D600%26pitch%3D2.2512462931385926%26panoid%3DvrYjBVqy23or2j3c9KfHwQ%26yaw%3D191.63699463385655!7i16384!8i8192!4m6!3m5!1s0x8866358a744ec2cf:0xf0cf40749a9898c2!8m2!3d36.875317!4d-85.6604178!16s%2Fg%2F11gwmr6b4p?entry=ttu&amp;g_ep=EgoyMDI1MDkxNC4wIKXMDSoASAFQAw%3D%3D">Google Maps</a> | AJ21: https://www.google.com/maps/place/4949+Summer+Shade+Rd,+Summer+Shade,+KY+42166/@36.8759171,-85.6601021,3a,37.5y,191.64h,87.75t/data=!3m7!1e1!3m5!1svrYjBVqy23or2j3c9KfHwQ!2e0!6shttps:%2F%2Fstreetviewpixels-pa.googleapis.com%2Fv1%2Fthumbnail%3Fcb_client%3Dmaps_sv.tactile%26w%3D900%26h%3D600%26pitch%3D2.2512462931385926%26panoid%3DvrYjBVqy23or2j3c9KfHwQ%26yaw%3D191.63699463385655!7i16384!8i8192!4m6!3m5!1s0x8866358a744ec2cf:0xf0cf40749a9898c2!8m2!3d36.875317!4d-85.6604178!16s%2Fg%2F11gwmr6b4p?entry=ttu&amp;g_ep=EgoyMDI1MDkxNC4wIKXMDSoASAFQAw%3D%3D">Google Maps</a>
C22: BLVIGABW | D22: WNS3282 | E22: Owned | F22: Building | G22: Central Office | H22: Warehouse | I22: 34.864025 | J22: -83.984809 | K22: 40 River Road Connector | L22: Blairsville | M22: GA | N22: B040040 | O22: 3293 | P22: REIT_ILEC | Q22: Windstream Standard| LLC | R22: ABS 1 | S22: 22270.31 | T22: 9585.47 | U22: 4510 | V22: 3953.58 | W22: 5000 | X22: 2 | Y22: 0 | Z22: 0 | AA22: 0 | AB22: 0 | AC22: 0 | AD22: 0 | AE22: 0 | AF22: 0 | AG22: 0 | AI22: https://sitefotos.com/vpics/guestmapdev?w0s7t4 | AJ22: =HYPERLINK(AI22,"LINK") -> LINK
C23: BLKLGAXA | D23: WNS0261 | E23: Owned | F23: Building | G23: Central Office | I23: 31.38254 | J23: -84.957519 | K23: 15166 River St | L23: Blakely | M23: GA | N23: ON049-GA-1001 | O23: 2356 | P23: REIT_ILEC | Q23: Windstream Georgia Telephone | R23: ABS 1 | S23: 13697.58 | T23: 39609.5 | U23: 2991.03 | V23: 13508.58 | W23: 5652 | X23: 35 | Y23: 994 | Z23: 352 | AA23: 1346 | AB23: 5815.9 | AC23: 8504.4 | AD23: 34336.85 | AE23: 14320.3 | AF23: 0 | AG23: 14320.3 | AI23: https://sitefotos.com/vpics/guestmapdev?m8q5k5 | AJ23: =HYPERLINK(AI23,"LINK") -> LINK
C24: BRFRFLXA | E24: Owned | F24: Building | G24: Central Office | I24: 29.960083 | J24: -82.927998 | K24: 108 Drane St Nw| Branford| FL| 32008 | L24: Branford | M24: FL | N24: ON047-FL-001 | P24: WIN_ILEC | Q24: Windstream Florida| Inc. | R24: ABS 2 | S24: 0 | T24: 0 | U24: 0 | V24: 0 | W24: 10685 | X24: 20 | Y24: 307 | Z24: 149 | AA24: 456 | AB24: 7600 | AC24: 17521.53 | AD24: 36194.05 | AE24: 25121.53 | AF24: 0 | AG24: 25121.53 | AI24: https://www.google.com/maps/place/34%C2%B002'16.7%22N+94%C2%B020'31.6%22W/@34.0379733,-94.3427548,136m/data=!3m2!1e3!4b1!4m4!3m3!8m2!3d34.0379722!4d-94.3421111?entry=ttu&amp;g_ep=EgoyMDI2MDMwMS4xIKXMDSoASAFQAw%3D%3D">Google Maps</a> | AJ24: =HYPERLINK(AI24,"LINK") -> LINK
C25: BRHDKYXA | E25: Owned | F25: Building | G25: Central Office | I25: 37.341683 | J25: -84.449908 | K25: 4297 Highway 70 | L25: BRODHEAD | M25: KY | N25: ON220-KY-038 | O25: 3951 | P25: REIT_ILEC | Q25: Windstream Kentucky East| LLC | R25: ABS 2 | S25: 0 | T25: 0 | U25: 0 | V25: 0 | W25: 10084 | X25: 14 | Y25: 115 | Z25: 147 | AA25: 262 | AB25: 0 | AC25: 7379 | AD25: 0 | AE25: 7379 | AF25: 0 | AG25: 7379 | AI25: https://www.google.com/maps/place/4949+Summer+Shade+Rd,+Summer+Shade,+KY+42166/@36.8759171,-85.6601021,3a,37.5y,191.64h,87.75t/data=!3m7!1e1!3m5!1svrYjBVqy23or2j3c9KfHwQ!2e0!6shttps:%2F%2Fstreetviewpixels-pa.googleapis.com%2Fv1%2Fthumbnail%3Fcb_client%3Dmaps_sv.tactile%26w%3D900%26h%3D600%26pitch%3D2.2512462931385926%26panoid%3DvrYjBVqy23or2j3c9KfHwQ%26yaw%3D191.63699463385655!7i16384!8i8192!4m6!3m5!1s0x8866358a744ec2cf:0xf0cf40749a9898c2!8m2!3d36.875317!4d-85.6604178!16s%2Fg%2F11gwmr6b4p?entry=ttu&amp;g_ep=EgoyMDI1MDkxNC4wIKXMDSoASAFQAw%3D%3D">Google Maps</a> | AJ25: https://www.google.com/maps/place/4949+Summer+Shade+Rd,+Summer+Shade,+KY+42166/@36.8759171,-85.6601021,3a,37.5y,191.64h,87.75t/data=!3m7!1e1!3m5!1svrYjBVqy23or2j3c9KfHwQ!2e0!6shttps:%2F%2Fstreetviewpixels-pa.googleapis.com%2Fv1%2Fthumbnail%3Fcb_client%3Dmaps_sv.tactile%26w%3D900%26h%3D600%26pitch%3D2.2512462931385926%26panoid%3DvrYjBVqy23or2j3c9KfHwQ%26yaw%3D191.63699463385655!7i16384!8i8192!4m6!3m5!1s0x8866358a744ec2cf:0xf0cf40749a9898c2!8m2!3d36.875317!4d-85.6604178!16s%2Fg%2F11gwmr6b4p?entry=ttu&amp;g_ep=EgoyMDI1MDkxNC4wIKXMDSoASAFQAw%3D%3D">Google Maps</a>
B26: Yes: 12k sqft + Owned | C26: BRAROKXA | D26: WNS2324 | E26: Owned | F26: Building | G26: Central Office | H26: Switch | I26: 36.052614 | J26: -95.791826 | K26: 114 West Broadway | L26: Broken Arrow | M26: OK | N26: ON200-OK-005 | O26: 34 | P26: REIT_ILEC | Q26: Valor Telecommunications of Texas| LLC | R26: ABS 2 | S26: 42692.94 | T26: 104993.98 | U26: 18556.6 | V26: 34474.51 | W26: 17085 | X26: 150 | Y26: 526 | Z26: 1508 | AA26: 2034 | AB26: 14122.6 | AC26: 13377.91 | AD26: 45891.26 | AE26: 27500.51 | AF26: 1011.97 | AG26: 28512.48 | AI26: https://www.sitefotos.com/vpics/guestmapdev?p2x4k3 | AJ26: =HYPERLINK(AI26,"LINK") -> LINK
B27: Yes: 12k sqft + Owned | C27: BRAROKXC | D27: WNS2325 | E27: Owned | F27: Building | G27: Central Office | H27: Switch | I27: 35.998678 | J27: -95.796852 | K27: 5301 South Elm Place W | L27: Broken Arrow | M27: OK | N27: ON200-OK-007 | O27: 41 | P27: REIT_ILEC | Q27: Valor Telecommunications of Texas| LLC | R27: ABS 2 | S27: 91043.67 | T27: 89430.4 | U27: 26395.93 | V27: 28858.43 | W27: 14330 | X27: 109 | Y27: 532 | Z27: 362 | AA27: 894 | AB27: 12002.37 | AC27: 3547.06 | AD27: 39317.23 | AE27: 15549.43 | AF27: 0 | AG27: 15549.43 | AI27: https://www.sitefotos.com/vpics/guestmapdev?w7d2n3 | AJ27: =HYPERLINK(AI27,"LINK") -> LINK
B28: Yes - High Rack count | C28: BRAROKXD | D28: WNS2327 | E28: Owned | F28: Building | G28: Central Office | H28: Switch | I28: 36.089602 | J28: -95.790558 | K28: 201 East Omaha Street | L28: Broken Arrow | M28: OK | N28: ON200-OK-009 | O28: 178 | P28: REIT_ILEC | Q28: Valor Telecommunications of Texas| LLC | R28: ABS 2 | S28: 38650.16 | T28: 47222.1 | U28: 2055.36 | V28: 21691.28 | W28: 4300 | X28: 106 | Y28: 396 | Z28: 404 | AA28: 800 | AB28: 13778.5 | AC28: 35254.89 | AD28: 35210.86 | AE28: 49033.39 | AF28: 0 | AG28: 49033.39 | AI28: https://www.sitefotos.com/vpics/guestmapdev?r2t1s4 | AJ28: =HYPERLINK(AI28,"LINK") -> LINK
C29: BRAROKXE | D29: WNS2326 | E29: Owned | F29: Building | G29: Central Office | H29: Switch | I29: 36.061524 | J29: -95.684298 | K29: 1025 North 84th Street | L29: Broken Arrow | M29: OK | N29: ON200-OK-008 | O29: 209 | P29: REIT_ILEC | Q29: Valor Telecommunications of Texas| LLC | R29: ABS 2 | S29: 15031.55 | T29: 40110.63 | U29: 1375.36 | V29: 18663.89 | W29: 3565 | X29: 38 | Y29: 255 | Z29: 457 | AA29: 712 | AB29: 2752.63 | AC29: 3798.56 | AD29: 40926.36 | AE29: 6551.19 | AF29: 0 | AG29: 6551.19 | AI29: https://www.sitefotos.com/vpics/guestmapdev?q8o0x5 | AJ29: =HYPERLINK(AI29,"LINK") -> LINK
C30: BKVLKYXA | D30: WNS1712 | E30: Owned | F30: Building | G30: Central Office | I30: 38.682502 | J30: -84.067487 | K30: 202 Madison St | L30: Brooksville | M30: KY | N30: ON220-KY-091 | P30: WIN_ILEC | Q30: Windstream Kentucky East| LLC | R30: ABS 1 | S30: 10535.54 | T30: 20537.39 | U30: 2580.34 | V30: 6646.59 | W30: 3062 | X30: 16 | Y30: 278 | Z30: 112 | AA30: 390 | AB30: 2080.92 | AC30: 13913.88 | AD30: 0 | AE30: 15994.8 | AF30: 0 | AG30: 15994.8 | AI30: https://www.sitefotos.com/vpics/guestmapdev?j4y4w6 | AJ30: =HYPERLINK(AI30,"LINK") -> LINK
B31: Yes: 12k sqft + Owned | C31: BWFDTXXA | E31: Owned | F31: Building | G31: Central Office | H31: Tower | I31: 33.17722 | J31: -102.27442 | K31: 101 East Tate | L31: Brownfield | M31: TX | N31: ON400-TX-1001 | O31: 2835 | P31: REIT_ILEC | R31: ABS 2 | S31: 0 | T31: 0 | U31: 0 | V31: 0 | W31: 12000 | X31: 93 | Y31: 291 | Z31: 714 | AA31: 1005 | AB31: 11734.8 | AC31: 39179.17 | AD31: 114449.47 | AE31: 50913.97 | AF31: 0 | AG31: 50913.97 | AH31: 42339 | AI31: https://www.sitefotos.com/vpics/guestmapdev?v4r7w8 | AJ31: =HYPERLINK(AI31,"LINK") -> LINK
C32: BRSDKYXA | D32: WNS1715 | E32: Owned | F32: Building | G32: Central Office | I32: 36.989789 | J32: -84.599373 | K32: 53 E French Ave 03 | L32: BURNSIDE | M32: KY | N32: ON219-KY-007 | O32: 182 | P32: REIT_ILEC | Q32: Windstream Kentucky East| LLC | R32: ABS 2 | S32: 17561.21 | T32: 45983.2 | U32: 2415.46 | V32: 18602.01 | W32: 4096 | X32: 41 | Y32: 131 | Z32: 534 | AA32: 665 | AB32: 0 | AC32: 12671.67 | AD32: 35664.33 | AE32: 12671.67 | AF32: 0 | AG32: 12671.67 | AI32: https://www.sitefotos.com/vpics/guestmapdev?m6f5w8 | AJ32: =HYPERLINK(AI32,"LINK") -> LINK
C33: CAIRGAXA | D33: WNS1480 | E33: Owned | F33: Building | G33: Central Office | H33: Switch | I33: 30.878532 | J33: -84.208973 | K33: 48 2nd Avenue | L33: Cairo | M33: GA | N33: ON041-GA-023 | O33: 238 | P33: REIT_ILEC | Q33: Windstream Georgia| LLC | R33: ABS 2 | S33: 18938.69 | T33: 61805.1 | U33: 3843.93 | V33: 23790.79 | W33: 3592 | X33: 37 | Y33: 425 | Z33: 1243 | AA33: 1668 | AB33: 8770.4 | AC33: 15857.7 | AD33: 29131.83 | AE33: 24628.1 | AF33: 0 | AG33: 24628.1 | AI33: https://sitefotos.com/vpics/guestmapdev?a6c5j7 | AJ33: =HYPERLINK(AI33,"LINK") -> LINK
C34: CLHNFLXA | D34: WNS1430 | E34: Owned | F34: Building | G34: Central Office | I34: 30.564356 | J34: -81.831421 | K34: 45403 Green Avenue | L34: Callahan | M34: FL | N34: ON047-FL-010 | O34: 2338 | P34: REIT_ILEC | Q34: Windstream Florida| Inc. | R34: ABS 2 | S34: 19452.03 | T34: 32431.16 | U34: 4816.32 | V34: 11011.12 | W34: 4560 | X34: 44 | Y34: 191 | Z34: 841 | AA34: 1032 | AB34: 4654.75 | AC34: 41608.82 | AD34: 14391 | AE34: 46263.57 | AF34: 0 | AG34: 46263.57 | AI34: https://www.google.com/maps/place/30%C2%B033'51.7%22N+81%C2%B049'53.1%22W/@30.5643623,-81.8320604,234m/data=!3m2!1e3!4b1!4m4!3m3!8m2!3d30.5643611!4d-81.8314167?entry=ttu&amp;g_ep=EgoyMDI2MDIyNC4wIKXMDSoASAFQAw%3D%3D">Google Maps</a> | AJ34: =HYPERLINK(AI34,"LINK") -> LINK
B35: Yes - High Rack count | C35: CMVLKYXA | D35: WNS1718 | E35: Owned | F35: Building | G35: Central Office | I35: 37.342599 | J35: -85.343916 | K35: 303 E Broadway | L35: Campbellsville | M35: KY | N35: ON219-KY-008 | P35: WIN_ILEC | Q35: Windstream Kentucky East| LLC | R35: ABS 2 | S35: 22230.25 | T35: 58783.53 | U35: 8095.15 | V35: 21965.42 | W35: 8877 | X35: 85 | Y35: 471 | Z35: 2243 | AA35: 2714 | AB35: 12345.65 | AC35: 70247.22 | AD35: 23338.55 | AE35: 82592.87 | AF35: 0 | AG35: 82592.87 | AH35: 42881 | AI35: https://www.google.com/maps/place/37%C2%B020'33.3%22N+85%C2%B020'38.1%22W/@37.3425844,-85.3445604,216m/data=!3m1!1e3!4m4!3m3!8m2!3d37.3425833!4d-85.3439167?entry=ttu&amp;g_ep=EgoyMDI1MTExNy4wIKXMDSoASAFQAw%3D%3D">Google Maps</a> | AJ35: =HYPERLINK(AI35,"LINK") -> LINK
B36: Yes - High Rack count | C36: CNTNGAXA | D36: WNS1482 | E36: Owned | F36: Building | G36: Central Office | I36: 34.23611 | J36: -84.490655 | K36: 190 South Church Street | L36: Canton | M36: GA | N36: ON042-GA-105 | O36: 106 | P36: REIT_ILEC | Q36: Windstream Georgia Communications| LLC | R36: ABS 1 | S36: 30559.41 | T36: 126734.91 | U36: 11829.91 | V36: 41202.68 | W36: 7075 | X36: 81 | Y36: 602 | Z36: 368 | AA36: 970 | AB36: 30521.33 | AC36: 44090.74 | AD36: 38562.74 | AE36: 74612.07 | AF36: 0 | AG36: 74612.07 | AH36: 43137 | AI36: https://www.google.com/maps/place/Kinetic+Fiber+Internet+-+Canton+GA/@34.2301179,-84.4892039,112m/data=!3m1!1e3!4m15!1m8!3m7!1s0x88f565bbe68ef9af:0xbf14ffe07e1ed3ad!2s206+Longview+St,+Canton,+GA+30114!3b1!8m2!3d34.2301135!4d-84.488882!16s%2Fg%2F11l0nhqjn7!3m5!1s0x88f6c7e1263eea59:0x4040cd808668f9ea!8m2!3d34.2300248!4d-84.4881739!16s%2Fg%2F1vc6f7d_?entry=ttu&amp;g_ep=EgoyMDI1MTExNy4wIKXMDSoASAFQAw%3D%3D">Google Maps</a> | AJ36: https://www.google.com/maps/place/Kinetic+Fiber+Internet+-+Canton+GA/@34.2301179,-84.4892039,112m/data=!3m1!1e3!4m15!1m8!3m7!1s0x88f565bbe68ef9af:0xbf14ffe07e1ed3ad!2s206+Longview+St,+Canton,+GA+30114!3b1!8m2!3d34.2301135!4d-84.488882!16s%2Fg%2F11l0nhqjn7!3m5!1s0x88f6c7e1263eea59:0x4040cd808668f9ea!8m2!3d34.2300248!4d-84.4881739!16s%2Fg%2F1vc6f7d_?entry=ttu&amp;g_ep=EgoyMDI1MTExNy4wIKXMDSoASAFQAw%3D%3D">Google Maps</a>
C37: CECLOHXA | D37: WNS2243 | E37: Owned | F37: Building | G37: Central Office | I37: 41.218146 | J37: -84.602126 | K37: 105 North Main Street | L37: CECIL | M37: OH | N37: ON158-OH-020 | O37: 2658 | P37: REIT_ILEC | Q37: Windstream Ohio| LLC | R37: ABS 2 | S37: 1685.44 | T37: 3350.59 | U37: 360.8 | V37: 2687.74 | W37: 4994 | X37: 5 | Y37: 48 | Z37: 0 | AA37: 48 | AB37: 0 | AC37: 0 | AD37: 0 | AE37: 0 | AF37: 0 | AG37: 0 | AI37: https://www.google.com/maps/place/41%C2%B013'05.3%22N+84%C2%B036'07.7%22W/@41.218151,-84.6027937,124m/data=!3m2!1e3!4b1!4m4!3m3!8m2!3d41.21815!4d-84.60215?entry=ttu&amp;g_ep=EgoyMDI1MTEyMy4xIKXMDSoASAFQAw%3D%3D">Google Maps</a> | AJ37: =HYPERLINK(AI37,"LINK") -> LINK
C38: CNVLIAXO | D38: WNS0461 | E38: Owned | F38: Building | G38: Central Office | I38: 40.732267 | J38: -92.876119 | K38: 236 West Maple Street | L38: Centerville | M38: IA | N38: ON132-IA-1064 | O38: 1659 | P38: REIT_ILEC | Q38: Windstream Iowa Communications| Inc. | R38: ABS 2 | S38: 13556.16 | T38: 35810.56 | U38: 3065.11 | V38: 12367.51 | W38: 9042 | X38: 19 | Y38: 422 | Z38: 557 | AA38: 979 | AB38: 1857 | AC38: 7733.11 | AD38: 3834.8 | AE38: 9590.11 | AF38: 0 | AG38: 9590.11 | AI38: https://www.sitefotos.com/vpics/guestmapdev?e6u3n8 | AJ38: =HYPERLINK(AI38,"LINK") -> LINK
C39: CNVLGAXA | D39: WNS1487 | E39: Owned | F39: Building | G39: Central Office | H39: Switch | I39: 32.623499 | J39: -83.687999 | K39: 109 Gunn Road | L39: Centerville | M39: GA | N39: ON041-GA-006 | O39: 252 | P39: REIT_ILEC | Q39: Windstream Georgia| LLC | R39: ABS 2 | S39: 8895.33 | T39: 23424.35 | U39: 1180.62 | V39: 5501.25 | W39: 2976 | X39: 23 | Y39: 261 | Z39: 190 | AA39: 451 | AB39: 14731.4 | AC39: 13827.45 | AD39: 11867.2 | AE39: 28558.85 | AF39: 0 | AG39: 28558.85 | AI39: https://sitefotos.com/vpics/guestmapdev?b2k2p1 | AJ39: =HYPERLINK(AI39,"LINK") -> LINK
B40: Yes: 12k sqft + Owned | C40: CHRDOHXA | D40: WNS2244 | E40: Owned | F40: Building | G40: Central Office | I40: 41.581285 | J40: -81.202133 | K40: 205 South Hambden Street | L40: Chardon | M40: OH | N40: ON080-OH-044 | O40: 2659 | P40: REIT_ILEC | Q40: Windstream Western Reserve| Inc. | R40: ABS 1 | S40: 82937.03 | T40: 102360.37 | U40: 30699.82 | V40: 32185.13 | W40: 12446 | X40: 100 | Y40: 647 | Z40: 575 | AA40: 1222 | AB40: 4888.4 | AC40: 90111.32 | AD40: 14874.4 | AE40: 94999.72 | AF40: 0 | AG40: 94999.72 | AI40: https://www.sitefotos.com/vpics/guestmapdev?k0u2x5 | AJ40: =HYPERLINK(AI40,"LINK") -> LINK
...

Sheet Top 50
A1: Inputs
B2: W/Sqft | C2: 250
B3: White space as % of whole | C3: 0.75
A6: MBN Selected? | B6: Selected? | C6: CLLI | D6: Site_Number | E6: Land_Ownership | F6: Asset_Type | G6: Primary_Use | H6: Secondary_Use | I6: LAT | J6: LONG | K6: Address | L6: City | M6: State | N6: Lease_ID | O6: REIT_ID | P6: Ownership | Q6: Entity_Name | R6: ABS_Category | S6: KOIOS - BSM 2025 | T6: KOIOS - UTILITIES 2025 | U6: KOIOS - BSM 2026 | V6: KOIOS - UTILITIES 2026 | W6: Square Ft-Interior | X6: Rack Count | Y6: KIN COPPER_SUBS | Z6: KIN FIBER_SUBS | AA6: KIN TOTAL_SUBS | AB6: Drop MRR | AC6: Drop MRR (Non OM) | AD6: Pass Through MRR | AE6: Drop MRR Total | AF6: COLO_MRR | AG6: Overall MRR Total | AH6: Min LEASE_ID - ExecutionDate | AI6: Site Photo Link | AJ6: TA: Est. site MW capacity (sqft based) | AK6: MW>5? | AL6: Eye test site attractiveness | AM6: Eye test site attractiveness explanation | AN6: Mireye lookup code | AO6: Mireye results | AP6: Mireye recommendation
A7: Y | B7: Yes: 12k sqft + Owned | C7: ASLDKYXA | D7: WNS1701 | E7: Owned | F7: Building | G7: Central Office | I7: 38.4758 | J7: -82.64385 | K7: 619 15th Street | L7: Ashland | M7: KY | N7: B2193221111 | O7: 3469 | P7: REIT_ILEC | Q7: Windstream Kentucky East| LLC | R7: ABS 1 | S7: 80399.73 | T7: 247287.21 | U7: 15495.96 | V7: 97031.63 | W7: 34184 | X7: 232 | Y7: 223 | Z7: 1165 | AA7: 1388 | AB7: 23231.37 | AC7: 120711.48 | AD7: 101921.69 | AE7: 143942.85 | AF7: 0 | AG7: 143942.85 | AH7: 42881 | AI7: https://www.sitefotos.com/vpics/guestmapdev?c2k3m2 | AJ7: =W7*$C$3*$C$2/10^6 -> 6.4095 | AK7: Y | AL7: Low | AM7: Dense, residential neighborhood. Limited space. | AP7: =INDEX('Mireye Site Screen'!BU:BU, MATCH('Top 50'!$I7, 'Mireye Site Screen'!$C:$C, 0)) -> REVIEW (5-15 MW band)
B8: Yes: 12k sqft + Owned | C8: MEDSKYXA | D8: WNS1703 | E8: Owned | F8: Building | G8: Central Office | I8: 38.40965 | J8: -82.713032 | K8: 9216 Highway 60 | L8: Ashland | M8: KY | N8: ON216-KY-002 | P8: WIN_ILEC | Q8: Windstream Kentucky East| LLC | R8: ABS 1 | S8: 56902.92 | T8: 87147.61 | U8: 18735.57 | V8: 34174.83 | W8: 12209 | X8: 76 | Y8: 281 | Z8: 1025 | AA8: 1306 | AB8: 16039.46 | AC8: 39822.17 | AD8: 92545.24 | AE8: 55861.63 | AF8: 0 | AG8: 55861.63 | AI8: https://www.sitefotos.com/vpics/guestmapdev?r3f5f4 | AJ8: =W8*$C$3*$C$2/10^6 -> 2.2891875 | AM8: significant additional wooded space; commercial area; residential on single side of parcel, set back from edge
B9: Yes: 12k sqft + Owned | C9: BNBGOHXA | D9: WNS1052 | E9: Owned | F9: Building | G9: Central Office | I9: 41.385699 | J9: -81.340629 | K9: 8425 Baindridge Road | L9: Bainbridge | M9: OH | N9: ON080-OH-003 | O9: 2020 | P9: REIT_ILEC | Q9: Windstream Western Reserve| Inc. | R9: ABS 1 | S9: 31055.14 | T9: 57971.48 | U9: 12785.38 | V9: 19898.04 | W9: 14355 | X9: 64 | Y9: 285 | Z9: 474 | AA9: 759 | AB9: 1021 | AC9: 7569.59 | AD9: 18040.8 | AE9: 8590.59 | AF9: 0 | AG9: 8590.59 | AI9: https://www.google.com/maps/place/8425+Bainbridge+Rd,+Chagrin+Falls,+OH+44023/@41.385724,-81.3409919,102m/data=!3m1!1e3!4m12!1m5!3m4!2zNDHCsDIzJzA4LjYiTiA4McKwMjAnMjYuNCJX!8m2!3d41.38572!4d-81.34067!3m5!1s0x88311a7811e73ce9:0x8ae504c98819a4a0!8m2!3d41.3857038!4d-81.3406819!16s%2Fg%2F11b8v5dgqb?entry=ttu&amp;g_ep=EgoyMDI1MTAwNy4wIKXMDSoASAFQAw%3D%3D">Google Maps</a> | AJ9: =W9*$C$3*$C$2/10^6 -> 2.6915625 | AM9: some parking lot, commercial space, but highly residential around site
A10: Y | B10: Yes: 12k sqft + Owned | C10: CRNLGA01 | D10: WNS0048 | E10: Owned | F10: Building | G10: Central Office | I10: 34.497208 | J10: -83.549978 | K10: 2000 Communications Boulevard | L10: Baldwin | M10: GA | N10: B040009 | O10: 3405 | P10: REIT_ILEC | Q10: Windstream Standard| LLC | R10: ABS 2 | S10: 0 | T10: 131239.21 | U10: 0 | V10: 35861.89 | W10: 55823 | X10: 11 | Y10: 541 | Z10: 0 | AA10: 541 | AB10: 0 | AC10: 0 | AD10: 1299 | AE10: 0 | AF10: 0 | AG10: 0 | AH10: 31383 | AI10: https://sitefotos.com/vpics/guestmapdev?g4t5f6 | AJ10: =W10*$C$3*$C$2/10^6 -> 10.466812 | AK10: Y | AL10: Strong | AM10: Middle of a field basically. Nothing but room. | AN10: 1 | AO10: =INDEX('Mireye Site Screen'!BU:BU, MATCH('Top 50'!$AN10, 'Mireye Site Screen'!$A:$A, 0)) -> GO | AP10: =INDEX('Mireye Site Screen'!BV:BV, MATCH('Top 50'!$AN10, 'Mireye Site Screen'!$A:$A, 0)) -> Pursue first - open Georgia Power capacity inquiry now
B11: Yes - High Rack count | C11: BEREKYXA | D11: WNS1709 | E11: Owned | F11: Building | G11: Central Office | H11: Switch | I11: 37.573344 | J11: -84.285739 | K11: 310 Center Street | L11: Berea | M11: KY | N11: ON219-KY-003 | O11: 227 | P11: REIT_ILEC | Q11: Windstream Kentucky East| LLC | R11: ABS 1 | S11: 17800.04 | T11: 51712.55 | U11: 4044.87 | V11: 16119.02 | W11: 3242 | X11: 90 | Y11: 166 | Z11: 846 | AA11: 1012 | AB11: 15989.08 | AC11: 57335.17 | AD11: 59842.41 | AE11: 73324.25 | AF11: 0 | AG11: 73324.25 | AH11: 42881 | AI11: https://www.sitefotos.com/vpics/guestmapdev?q6e1d4 | AJ11: =W11*$C$3*$C$2/10^6 -> 0.607875 | AM11: corner of what looks like agricultural land.
B12: Yes: 12k sqft + Owned | C12: BRAROKXA | D12: WNS2324 | E12: Owned | F12: Building | G12: Central Office | H12: Switch | I12: 36.052614 | J12: -95.791826 | K12: 114 West Broadway | L12: Broken Arrow | M12: OK | N12: ON200-OK-005 | O12: 34 | P12: REIT_ILEC | Q12: Valor Telecommunications of Texas| LLC | R12: ABS 2 | S12: 42692.94 | T12: 104993.98 | U12: 18556.6 | V12: 34474.51 | W12: 17085 | X12: 150 | Y12: 526 | Z12: 1508 | AA12: 2034 | AB12: 14122.6 | AC12: 13377.91 | AD12: 45891.26 | AE12: 27500.51 | AF12: 1011.97 | AG12: 28512.48 | AI12: https://www.sitefotos.com/vpics/guestmapdev?p2x4k3 | AJ12: =W12*$C$3*$C$2/10^6 -> 3.2034375
B13: Yes: 12k sqft + Owned | C13: BRAROKXC | D13: WNS2325 | E13: Owned | F13: Building | G13: Central Office | H13: Switch | I13: 35.998678 | J13: -95.796852 | K13: 5301 South Elm Place W | L13: Broken Arrow | M13: OK | N13: ON200-OK-007 | O13: 41 | P13: REIT_ILEC | Q13: Valor Telecommunications of Texas| LLC | R13: ABS 2 | S13: 91043.67 | T13: 89430.4 | U13: 26395.93 | V13: 28858.43 | W13: 14330 | X13: 109 | Y13: 532 | Z13: 362 | AA13: 894 | AB13: 12002.37 | AC13: 3547.06 | AD13: 39317.23 | AE13: 15549.43 | AF13: 0 | AG13: 15549.43 | AI13: https://www.sitefotos.com/vpics/guestmapdev?w7d2n3 | AJ13: =W13*$C$3*$C$2/10^6 -> 2.686875
B14: Yes - High Rack count | C14: BRAROKXD | D14: WNS2327 | E14: Owned | F14: Building | G14: Central Office | H14: Switch | I14: 36.089602 | J14: -95.790558 | K14: 201 East Omaha Street | L14: Broken Arrow | M14: OK | N14: ON200-OK-009 | O14: 178 | P14: REIT_ILEC | Q14: Valor Telecommunications of Texas| LLC | R14: ABS 2 | S14: 38650.16 | T14: 47222.1 | U14: 2055.36 | V14: 21691.28 | W14: 4300 | X14: 106 | Y14: 396 | Z14: 404 | AA14: 800 | AB14: 13778.5 | AC14: 35254.89 | AD14: 35210.86 | AE14: 49033.39 | AF14: 0 | AG14: 49033.39 | AI14: https://www.sitefotos.com/vpics/guestmapdev?r2t1s4 | AJ14: =W14*$C$3*$C$2/10^6 -> 0.80625
B15: Yes: 12k sqft + Owned | C15: BWFDTXXA | E15: Owned | F15: Building | G15: Central Office | H15: Tower | I15: 33.17722 | J15: -102.27442 | K15: 101 East Tate | L15: Brownfield | M15: TX | N15: ON400-TX-1001 | O15: 2835 | P15: REIT_ILEC | R15: ABS 2 | S15: 0 | T15: 0 | U15: 0 | V15: 0 | W15: 12000 | X15: 93 | Y15: 291 | Z15: 714 | AA15: 1005 | AB15: 11734.8 | AC15: 39179.17 | AD15: 114449.47 | AE15: 50913.97 | AF15: 0 | AG15: 50913.97 | AH15: 42339 | AI15: https://www.sitefotos.com/vpics/guestmapdev?v4r7w8 | AJ15: =W15*$C$3*$C$2/10^6 -> 2.25
B16: Yes - High Rack count | C16: CMVLKYXA | D16: WNS1718 | E16: Owned | F16: Building | G16: Central Office | I16: 37.342599 | J16: -85.343916 | K16: 303 E Broadway | L16: Campbellsville | M16: KY | N16: ON219-KY-008 | P16: WIN_ILEC | Q16: Windstream Kentucky East| LLC | R16: ABS 2 | S16: 22230.25 | T16: 58783.53 | U16: 8095.15 | V16: 21965.42 | W16: 8877 | X16: 85 | Y16: 471 | Z16: 2243 | AA16: 2714 | AB16: 12345.65 | AC16: 70247.22 | AD16: 23338.55 | AE16: 82592.87 | AF16: 0 | AG16: 82592.87 | AH16: 42881 | AI16: https://www.google.com/maps/place/37%C2%B020'33.3%22N+85%C2%B020'38.1%22W/@37.3425844,-85.3445604,216m/data=!3m1!1e3!4m4!3m3!8m2!3d37.3425833!4d-85.3439167?entry=ttu&amp;g_ep=EgoyMDI1MTExNy4wIKXMDSoASAFQAw%3D%3D">Google Maps</a> | AJ16: =W16*$C$3*$C$2/10^6 -> 1.6644375
B17: Yes - High Rack count | C17: CNTNGAXA | D17: WNS1482 | E17: Owned | F17: Building | G17: Central Office | I17: 34.23611 | J17: -84.490655 | K17: 190 South Church Street | L17: Canton | M17: GA | N17: ON042-GA-105 | O17: 106 | P17: REIT_ILEC | Q17: Windstream Georgia Communications| LLC | R17: ABS 1 | S17: 30559.41 | T17: 126734.91 | U17: 11829.91 | V17: 41202.68 | W17: 7075 | X17: 81 | Y17: 602 | Z17: 368 | AA17: 970 | AB17: 30521.33 | AC17: 44090.74 | AD17: 38562.74 | AE17: 74612.07 | AF17: 0 | AG17: 74612.07 | AH17: 43137 | AI17: https://www.google.com/maps/place/Kinetic+Fiber+Internet+-+Canton+GA/@34.2301179,-84.4892039,112m/data=!3m1!1e3!4m15!1m8!3m7!1s0x88f565bbe68ef9af:0xbf14ffe07e1ed3ad!2s206+Longview+St,+Canton,+GA+30114!3b1!8m2!3d34.2301135!4d-84.488882!16s%2Fg%2F11l0nhqjn7!3m5!1s0x88f6c7e1263eea59:0x4040cd808668f9ea!8m2!3d34.2300248!4d-84.4881739!16s%2Fg%2F1vc6f7d_?entry=ttu&amp;g_ep=EgoyMDI1MTExNy4wIKXMDSoASAFQAw%3D%3D">Google Maps</a> | AJ17: =W17*$C$3*$C$2/10^6 -> 1.3265625
B18: Yes: 12k sqft + Owned | C18: CHRDOHXA | D18: WNS2244 | E18: Owned | F18: Building | G18: Central Office | I18: 41.581285 | J18: -81.202133 | K18: 205 South Hambden Street | L18: Chardon | M18: OH | N18: ON080-OH-044 | O18: 2659 | P18: REIT_ILEC | Q18: Windstream Western Reserve| Inc. | R18: ABS 1 | S18: 82937.03 | T18: 102360.37 | U18: 30699.82 | V18: 32185.13 | W18: 12446 | X18: 100 | Y18: 647 | Z18: 575 | AA18: 1222 | AB18: 4888.4 | AC18: 90111.32 | AD18: 14874.4 | AE18: 94999.72 | AF18: 0 | AG18: 94999.72 | AI18: https://www.sitefotos.com/vpics/guestmapdev?k0u2x5 | AJ18: =W18*$C$3*$C$2/10^6 -> 2.333625
B19: Yes: 12k sqft + Owned | C19: CHTHOKXD | E19: Owned | F19: Building | G19: Central Office | I19: 35.470961 | J19: -95.523631 | K19: 115 Northwest 1st Street | L19: Checotah | M19: OK | N19: ON200-OK-010 | O19: 302 | P19: REIT_ILEC | Q19: Valor Telecommunications of Texas| LLC | R19: ABS 2 | S19: 0 | T19: 0 | U19: 0 | V19: 0 | W19: 20000 | X19: 21 | Y19: 290 | Z19: 499 | AA19: 789 | AB19: 3684 | AC19: 3256.33 | AD19: 1292 | AE19: 6940.33 | AF19: 0 | AG19: 6940.33 | AH19: 42339 | AI19: https://www.google.com/maps/place/130+Howell+Dr,+Elizabethtown,+KY+42701/@37.7137354,-85.8271202,860m/data=!3m2!1e3!4b1!4m6!3m5!1s0x8868ef14cb372ebf:0xa1909efe4828c1f5!8m2!3d37.7137312!4d-85.8245453!16s%2Fg%2F11bw4nx7h4?entry=ttu&amp;g_ep=EgoyMDI2MDIwNC4wIKXMDSoASAFQAw%3D%3D">Google Maps</a> | AJ19: =W19*$C$3*$C$2/10^6 -> 3.75
B20: Yes: 12k sqft + Owned | C20: CHGVNCXA | D20: WNS1906 | E20: Owned | F20: Building | G20: Central Office | I20: 35.556922 | J20: -80.595882 | K20: 1525 South Main Street | L20: China Grove | M20: NC | N20: B018190 | O20: 2511 | P20: REIT_ILEC | Q20: Windstream Concord Telephone| LLC | R20: ABS 2 | S20: 16498.61 | T20: 24010.91 | U20: 17096.62 | V20: 7610.97 | W20: 12000 | X20: 38 | Y20: 184 | Z20: 1898 | AA20: 2082 | AB20: 6142 | AC20: 3830.7 | AD20: 85095.52 | AE20: 9972.7 | AF20: 0 | AG20: 9972.7 | AH20: 41883 | AI20: https://www.sitefotos.com/vpics/guestmapdev?n7j7q5 | AJ20: =W20*$C$3*$C$2/10^6 -> 2.25
B21: Yes - High Rack count | C21: CLEVGAXA | D21: WNS1491 | E21: Owned | F21: Building | G21: Central Office | I21: 34.597027 | J21: -83.766127 | K21: 158 West Kytle Street | L21: Cleveland | M21: GA | N21: ON040-GA-120 | O21: 200 | P21: REIT_ILEC | Q21: Windstream Standard| LLC | R21: ABS 1 | S21: 11195.13 | T21: 113494.35 | U21: 5552.62 | V21: 37854.63 | W21: 3688 | X21: 124 | Y21: 1025 | Z21: 257 | AA21: 1282 | AB21: 10847.39 | AC21: 71876.55 | AD21: 64725.86 | AE21: 82723.94 | AF21: 0 | AG21: 82723.94 | AH21: 42881 | AI21: https://sitefotos.com/vpics/guestmapdev?e5b4u1 | AJ21: =W21*$C$3*$C$2/10^6 -> 0.6915
A22: Y | B22: Yes - High Rack count | C22: CMRCGAXA | D22: WNS1495 | E22: Owned | F22: Building | G22: Central Office | I22: 34.203976 | J22: -83.459471 | K22: 45 Georgia Avenue | L22: Commerce | M22: GA | N22: ON041-GA-001 | O22: 76 | P22: REIT_ILEC | Q22: Windstream Georgia| LLC | R22: ABS 1 | S22: 52795.68 | T22: 300789.85 | U22: 21756.39 | V22: 113603.09 | W22: 9417 | X22: 128 | Y22: 815 | Z22: 465 | AA22: 1280 | AB22: 192014.29 | AC22: 208054.34 | AD22: 263492.71 | AE22: 400068.63 | AF22: 0 | AG22: 400068.63 | AH22: 42881 | AI22: https://sitefotos.com/vpics/guestmapdev?o0d4c1 | AJ22: =W22*$C$3*$C$2/10^6 -> 1.7656875
A23: Y | B23: Yes: 12k sqft + Owned | C23: ELYROHXA | D23: WNS2262 | E23: Owned | F23: Building | G23: Central Office | I23: 41.365741 | J23: -82.109993 | K23: 363 3rd Street | L23: Elyria | M23: OH | N23: B158010 | O23: 2674 | P23: REIT_ILEC | Q23: Windstream Ohio| LLC | R23: ABS 1 | S23: 94411.73 | T23: 341674.15 | U23: 37852.57 | V23: 100578.63 | W23: 73218 | X23: 159 | Y23: 1304 | Z23: 1087 | AA23: 2391 | AB23: 2448.53 | AC23: 61314.71 | AD23: 48268.88 | AE23: 63763.24 | AF23: 0 | AG23: 63763.24 | AH23: 42881 | AI23: https://www.sitefotos.com/vpics/guestmapdev?i3h7y0 | AJ23: =W23*$C$3*$C$2/10^6 -> 13.728375 | AK23: Y | AL23: Medium | AM23: Some parking lot, commercial space, but highly residential around site | AP23: =INDEX('Mireye Site Screen'!BU:BU, MATCH('Top 50'!$I23, 'Mireye Site Screen'!$C:$C, 0)) -> #N/A
A24: Y | B24: Yes: 12k sqft + Owned | C24: FTZGGAXA | D24: WNS1514 | E24: Owned | F24: Building | G24: Central Office | I24: 31.715144 | J24: -83.253794 | K24: 110 East Central | L24: Fitzgerald | M24: GA | N24: ON042-GA-132 | O24: 35 | P24: REIT_ILEC | Q24: Windstream Georgia Communications| LLC | R24: ABS 2 | S24: 46961.1 | T24: 316512.79 | U24: 15698.45 | V24: 74237.68 | W24: 16821 | X24: 92 | Y24: 442 | Z24: 1527 | AA24: 1969 | AB24: 242075.11 | AC24: 312077.57 | AD24: 173549.1 | AE24: 554152.68 | AF24: 0 | AG24: 554152.68 | AH24: 42767 | AI24: https://sitefotos.com/vpics/guestmapdev?g7s2j2 | AJ24: =W24*$C$3*$C$2/10^6 -> 3.1539375
B25: Yes: 12k sqft + Owned | C25: GENVOHXA | D25: WNS2267 | E25: Owned | F25: Building | G25: Central Office | I25: 41.805317 | J25: -80.945672 | K25: 37 South Forest Street | L25: Geneva | M25: OH | N25: ON080-OH-040 | O25: 51 | P25: REIT_ILEC | Q25: Windstream Western Reserve| Inc. | R25: ABS 1 | S25: 43683.77 | T25: 37088.83 | U25: 14547.93 | V25: 13944.09 | W25: 12477 | X25: 25 | Y25: 326 | Z25: 797 | AA25: 1123 | AB25: 3910 | AC25: 4547.86 | AD25: 9739.4 | AE25: 8457.86 | AF25: 0 | AG25: 8457.86 | AI25: https://www.sitefotos.com/vpics/guestmapdev?a0g2a6 | AJ25: =W25*$C$3*$C$2/10^6 -> 2.3394375
B26: Yes: 12k sqft + Owned | C26: GNBRARXA | D26: WNS1370 | E26: Owned | F26: Building | G26: Central Office | I26: 35.232663 | J26: -92.388351 | K26: 9 South Broadview Street | L26: Greenbrier | M26: AR | N26: ON202-AR-013 | O26: 2298 | P26: REIT_ILEC | Q26: Windstream Arkansas| LLC | R26: ABS 1 | S26: 57457.22 | T26: 86295.67 | U26: 23436.5 | V26: 19649.56 | W26: 20000 | X26: 64 | Y26: 331 | Z26: 324 | AA26: 655 | AB26: 8811.8 | AC26: 20476.55 | AD26: 63414.33 | AE26: 29288.35 | AF26: 0 | AG26: 29288.35 | AH26: 42881 | AI26: https://www.sitefotos.com/vpics/guestmapdev?e4o1u0 | AJ26: =W26*$C$3*$C$2/10^6 -> 3.75
A27: Y | B27: Yes: 12k sqft + Owned | C27: GRNLIAXC | D27: WNS1631 | E27: Owned | F27: Building | G27: Central Office | I27: 41.74517 | J27: -92.725415 | K27: 1010 Main Street | L27: Grinnell | M27: IA | N27: ON132-IA-1181 | O27: 37 | P27: REIT_ILEC | Q27: Windstream Iowa Communications| Inc. | R27: ABS 2 | S27: 37252.22 | T27: 109942.31 | U27: 21509.57 | V27: 40362.96 | W27: 15723 | X27: 84 | Y27: 648 | Z27: 595 | AA27: 1243 | AB27: 86783.49 | AC27: 175897.93 | AD27: 71294.07 | AE27: 262681.42 | AF27: 21 | AG27: 262702.42 | AI27: https://www.sitefotos.com/vpics/guestmapdev?s1u7o1 | AJ27: =W27*$C$3*$C$2/10^6 -> 2.9480625
B28: Yes: 12k sqft + Owned | C28: HRSNARXA | E28: Owned | F28: Building | G28: Central Office | I28: 36.214283 | J28: -93.079052 | K28: 202 Graham Street | L28: Harrison | M28: AR | N28: B202322 | O28: 1392 | P28: REIT_ILEC | Q28: Windstream Arkansas| LLC | R28: ABS 1 | S28: 149943.27 | T28: 97350.18 | U28: 58606.83 | V28: 23685.58 | W28: 21579 | X28: 81 | Y28: 472 | Z28: 144 | AA28: 616 | AB28: 12764 | AC28: 53237.64 | AD28: 52403.81 | AE28: 66001.64 | AF28: 0 | AG28: 66001.64 | AH28: 41831 | AI28: https://www.sitefotos.com/vpics/guestmapdev?o8a8x4 | AJ28: =W28*$C$3*$C$2/10^6 -> 4.0460625 | AK28: Y | AL28: Strong | AM28: Middle of a field basically. Room for days. | AN28: 2 | AO28: =INDEX('Mireye Site Screen'!BU:BU, MATCH('Top 50'!$AN28, 'Mireye Site Screen'!$A:$A, 0)) -> GO (leaning) | AP28: =INDEX('Mireye Site Screen'!BV:BV, MATCH('Top 50'!$AN28, 'Mireye Site Screen'!$A:$A, 0)) -> Pursue #2 - geotech karst study for expansion footprint + Entergy capacity inquiry in parallel
A29: Y | B29: Yes: 12k sqft + Owned | C29: HZRDKYXA | D29: WNS1739 | E29: Owned | F29: Building | G29: Central Office | I29: 37.249865 | J29: -83.19392 | K29: 101 Winterberry Drive | L29: Hazard | M29: KY | N29: ON219-KY-021 | O29: 42 | P29: REIT_ILEC | Q29: Windstream Kentucky East| LLC | R29: ABS 1 | S29: 46258.55 | T29: 118939.09 | U29: 9698.41 | V29: 42853.88 | W29: 14149 | X29: 133 | Y29: 624 | Z29: 1401 | AA29: 2025 | AB29: 48976.38 | AC29: 165196.62 | AD29: 31654.32 | AE29: 214173 | AF29: 0 | AG29: 214173 | AH29: 42614 | AI29: https://www.sitefotos.com/vpics/guestmapdev?i6e5b4 | AJ29: =W29*$C$3*$C$2/10^6 -> 2.6529375
A30: Y | B30: Yes: 12k sqft + Owned | C30: HDSNOHXB | D30: WNS1063 | E30: Owned | F30: Building | G30: Central Office | I30: 41.217063 | J30: -81.442508 | K30: 1300 Terex Road | L30: Hudson | M30: OH | N30: ON080-OH-015 | O30: 2031 | P30: REIT_ILEC | Q30: Windstream Western Reserve| Inc. | R30: ABS 1 | S30: 10196.96 | T30: 22058.62 | U30: 3969.1 | V30: 5551.47 | W30: 29978 | X30: 20 | Y30: 167 | Z30: 5 | AA30: 172 | AB30: 390 | AC30: 3113 | AD30: 481 | AE30: 3503 | AF30: 0 | AG30: 3503 | AI30: https://www.sitefotos.com/vpics/guestmapdev?u1a0v7 | AJ30: =W30*$C$3*$C$2/10^6 -> 5.620875 | AK30: Y | AL30: Strong | AM30: Corner of what looks like agricultural land. | AN30: 3 | AO30: =INDEX('Mireye Site Screen'!BU:BU, MATCH('Top 50'!$AN30, 'Mireye Site Screen'!$A:$A, 0)) -> REVIEW | AP30: =INDEX('Mireye Site Screen'!BV:BV, MATCH('Top 50'!$AN30, 'Mireye Site Screen'!$A:$A, 0)) -> Advance - gauge Hudson Public Power capacity appetite for the increment; spec Tier 4 gensets
A31: Y | B31: Yes: 12k sqft + Owned | C31: HDSNOHXA | D31: WNS2275 | E31: Owned | F31: Building | G31: Central Office | I31: 41.243414 | J31: -81.440034 | K31: 245 North Main Street | L31: Hudson | M31: OH | N31: ON080-OH-043 | O31: 3800 | P31: REIT_ILEC | Q31: Windstream Western Reserve| Inc. | R31: ABS 1 | S31: 151219.15 | T31: 292937.87 | U31: 42853.14 | V31: 87782.52 | W31: 18705 | X31: 170 | Y31: 486 | Z31: 241 | AA31: 727 | AB31: 119468.81 | AC31: 211677.8 | AD31: 26906.52 | AE31: 331146.61 | AF31: 0 | AG31: 331146.61 | AH31: 39417 | AI31: https://sitefotos.com/vpics/guestmapdev?u6l0o6 | AJ31: =W31*$C$3*$C$2/10^6 -> 3.5071875
B32: Yes: 12k sqft + Owned | C32: KRVLTXXA | D32: WNS2631 | E32: Owned | F32: Building | G32: Central Office | I32: 30.045348 | J32: -99.139977 | K32: 812 Water Street | L32: Kerrville | M32: TX | N32: ON810-TX-009 | O32: 2899 | P32: REIT_ILEC | Q32: Windstream Communications Kerrville| LLC | R32: ABS 1 | S32: 44982.18 | T32: 68041.94 | U32: 10368.24 | V32: 23709.36 | W32: 24782 | X32: 144 | Y32: 720 | Z32: 787 | AA32: 1507 | AB32: 13942.9 | AC32: 48060.79 | AD32: 4423 | AE32: 62003.69 | AF32: 0 | AG32: 62003.69 | AH32: 39507 | AI32: https://www.sitefotos.com/vpics/guestmapdev?g2e5m3 | AJ32: =W32*$C$3*$C$2/10^6 -> 4.646625 | AK32: Y | AL32: Medium/Low | AM32: Dense industrial area. Parking lot behind but expect it may be too dense. | AP32: =INDEX('Mireye Site Screen'!BU:BU, MATCH('Top 50'!$I32, 'Mireye Site Screen'!$C:$C, 0)) -> #N/A
B33: Yes: 12k sqft + Owned | C33: LVLDTXXA | D33: WNS2638 | E33: Owned | F33: Building | G33: Central Office | H33: Tower | I33: 33.588056 | J33: -102.37954 | K33: 506 Avenue I | L33: Levelland | M33: TX | N33: ON400-01-054 | O33: 2215 | P33: REIT_ILEC | Q33: Valor Telecommunications of Texas| LLC | R33: ABS 2 | S33: 62293.72 | T33: 37529.42 | U33: 20677.18 | V33: 15123.29 | W33: 12108 | X33: 75 | Y33: 280 | Z33: 684 | AA33: 964 | AB33: 8290 | AC33: 24438.57 | AD33: 3619 | AE33: 32728.57 | AF33: 0 | AG33: 32728.57 | AH33: 42583 | AI33: https://www.sitefotos.com/vpics/guestmapdev?p2h0f6 | AJ33: =W33*$C$3*$C$2/10^6 -> 2.27025
B34: Yes: 12k sqft + Owned | C34: LVOKFLXA | D34: WNS1448 | E34: Owned | F34: Building | G34: Central Office | I34: 30.293973 | J34: -82.982079 | K34: 206 White Avenue SE | L34: Live Oak | M34: FL | N34: ON047-FL-1012 | O34: 2347 | P34: REIT_ILEC | Q34: Windstream Florida| Inc. | R34: ABS 2 | S34: 177616.39 | T34: 165791.72 | U34: 20604.42 | V34: 59604.05 | W34: 21370 | X34: 123 | Y34: 774 | Z34: 856 | AA34: 1630 | AB34: 67011.38 | AC34: 100782.94 | AD34: 50269.76 | AE34: 167794.32 | AF34: 1027.52 | AG34: 168821.84 | AH34: 39173 | AI34: https://www.google.com/maps/place/30%C2%B017'38.3%22N+82%C2%B058'56.0%22W/@30.2939734,-82.9828659,179m/data=!3m2!1e3!4b1!4m4!3m3!8m2!3d30.2939722!4d-82.9822222?entry=ttu&amp;g_ep=EgoyMDI2MDIyNC4wIKXMDSoASAFQAw%3D%3D">Google Maps</a> | AJ34: =W34*$C$3*$C$2/10^6 -> 4.006875 | AK34: Y | AL34: Medium | AM34: Relatively dense commercial + residential | AP34: =INDEX('Mireye Site Screen'!BU:BU, MATCH('Top 50'!$I34, 'Mireye Site Screen'!$C:$C, 0)) -> #N/A
B35: Yes: 12k sqft + Owned | C35: MDVLGAXA | D35: WNS1550 | E35: Owned | F35: Building | G35: Central Office | I35: 33.090815 | J35: -83.228473 | K35: 750 North Jefferson Street | L35: Milledgeville | M35: GA | N35: ON042-GA-103 | O35: 19 | P35: REIT_ILEC | Q35: Windstream Georgia Communications| LLC | R35: ABS 2 | S35: 86249.72 | T35: 156249.37 | U35: 45893.97 | V35: 50239.29 | W35: 25764 | X35: 93 | Y35: 1016 | Z35: 346 | AA35: 1362 | AB35: 40278.47 | AC35: 76847.68 | AD35: 212148.55 | AE35: 117126.15 | AF35: 0 | AG35: 117126.15 | AH35: 42881 | AI35: https://sitefotos.com/vpics/guestmapdev?t5n6n8 | AJ35: =W35*$C$3*$C$2/10^6 -> 4.83075 | AK35: Y | AL35: Medium | AM35: Space on the block but looks like it's residential; expect limited availability; exception is relatively large parking space which seems to serve only this building. | AP35: =INDEX('Mireye Site Screen'!BU:BU, MATCH('Top 50'!$I35, 'Mireye Site Screen'!$C:$C, 0)) -> #N/A
A36: Y | B36: Yes: 12k sqft + Owned | C36: MRHDKYXA | D36: WNS1776 | E36: Owned | F36: Building | G36: Central Office | H36: Switch | I36: 38.183664 | J36: -83.434779 | K36: 154 East 2nd Street | L36: Morehead | M36: KY | N36: ON219-KY-033 | O36: 23 | P36: REIT_ILEC | Q36: Windstream Kentucky East| LLC | R36: ABS 1 | S36: 37578.36 | T36: 109271.36 | U36: 6631.25 | V36: 39402.98 | W36: 23104 | X36: 160 | Y36: 263 | Z36: 407 | AA36: 670 | AB36: 17854.9 | AC36: 107767.71 | AD36: 81907.1 | AE36: 125622.61 | AF36: 0 | AG36: 125622.61 | AI36: https://www.sitefotos.com/vpics/guestmapdev?q5b1t3 | AJ36: =W36*$C$3*$C$2/10^6 -> 4.332 | AK36: Y | AL36: Medium | AM36: Relatively dense commercial | AP36: =INDEX('Mireye Site Screen'!BU:BU, MATCH('Top 50'!$I36, 'Mireye Site Screen'!$C:$C, 0)) -> #N/A
B37: Yes: 12k sqft + Owned | C37: MLTRGAXA | D37: WNS1556 | E37: Owned | F37: Building | G37: Central Office | I37: 31.177483 | J37: -83.783714 | K37: 216 4th Street SE | L37: Moultrie | M37: GA | N37: ON042-GA-131 | O37: 20 | P37: REIT_ILEC | Q37: Windstream Georgia Communications| LLC | R37: ABS 1 | S37: 44518.26 | T37: 130268.76 | U37: 32316.68 | V37: 39313.9 | W37: 25380 | X37: 89 | Y37: 460 | Z37: 2509 | AA37: 2969 | AB37: 13721 | AC37: 107934.84 | AD37: 34945.33 | AE37: 121655.84 | AF37: 0 | AG37: 121655.84 | AH37: 42881 | AI37: https://sitefotos.com/vpics/guestmapdev?u2o1q0 | AJ37: =W37*$C$3*$C$2/10^6 -> 4.75875 | AK37: Y | AL37: Medium/Strong | AM37: Space on the lot but relatively dense around it | AN37: 4 | AO37: =INDEX('Mireye Site Screen'!BU:BU, MATCH('Top 50'!$AN37, 'Mireye Site Screen'!$A:$A, 0)) -> REVIEW | AP37: =INDEX('Mireye Site Screen'!BV:BV, MATCH('Top 50'!$AN37, 'Mireye Site Screen'!$A:$A, 0)) -> Hold as OZ-advantaged backup; Phase I environmental if advanced
B38: Yes: 12k sqft + Owned | C38: MLTRGA05 | D38: WNS0398 | E38: Owned | F38: Building | G38: Central Office | H38: Warehouse | I38: 31.17919 | J38: -83.748761 | K38: 282 Industrial Drive | L38: Moultrie | M38: GA | N38: B042274 | O38: 3432 | P38: REIT_ILEC | Q38: Windstream Georgia Communications| LLC | R38: ABS 1 | S38: 63723.57 | T38: 35179.59 | U38: 23980.62 | V38: 9833.75 | W38: 15016 | X38: 4 | Y38: 0 | Z38: 0 | AA38: 0 | AB38: 0 | AC38: 0 | AD38: 0 | AE38: 0 | AF38: 0 | AG38: 0 | AI38: https://www.sitefotos.com/vpics/guestmapdev?g0p7o8 | AJ38: =W38*$C$3*$C$2/10^6 -> 2.8155
A39: Y | B39: Yes: 12k sqft + Owned | C39: NWRKOHXA | D39: WNS2289 | E39: Owned | F39: Building | G39: Central Office | I39: 40.059449 | J39: -82.404873 | K39: 66 North 4th Street | L39: Newark | M39: OH | N39: ON158-OH-024 | O39: 2693 | P39: REIT_ILEC | Q39: Windstream Ohio| LLC | R39: ABS 2 | S39: 49396.64 | T39: 121164.43 | U39: 30226.23 | V39: 45375.08 | W39: 35563 | X39: 145 | Y39: 717 | Z39: 1236 | AA39: 1953 | AB39: 6099.45 | AC39: 28989.82 | AD39: 57489.56 | AE39: 35089.27 | AF39: 0 | AG39: 35089.27 | AI39: https://www.sitefotos.com/vpics/guestmapdev?d8r3s3 | AJ39: =W39*$C$3*$C$2/10^6 -> 6.6680625 | AK39: Y | AL39: Medium/Strong | AM39: Little to no room for expansion, but enough interior sq ft for significant MW IT if power available | AN39: 5 | AO39: =INDEX('Mireye Site Screen'!BU:BU, MATCH('Top 50'!$AN39, 'Mireye Site Screen'!$A:$A, 0)) -> REVIEW (5-15 MW band) | AP39: =INDEX('Mireye Site Screen'!BV:BV, MATCH('Top 50'!$AN39, 'Mireye Site Screen'!$A:$A, 0)) -> Keep as low-band expansion candidate - AEP capacity inquiry decides it
A40: Y | B40: Yes: 12k sqft + Owned | C40: NWTNIAXC | D40: WNS1656 | E40: Owned | F40: Building | G40: Central Office | I40: 41.698332 | J40: -93.054486 | K40: 115 S Second Ave W | L40: Newton | M40: IA | N40: ON132-IA-01178 | O40: 2411 | P40: REIT_ILEC | Q40: Windstream Iowa Communications| Inc. | R40: ABS 2 | S40: 143343.34 | T40: 91808.72 | U40: 31658.36 | V40: 22200.06 | W40: 43934 | X40: 60 | Y40: 862 | Z40: 1789 | AA40: 2651 | AB40: 7531.78 | AC40: 39884.18 | AD40: 90116.1 | AE40: 47415.96 | AF40: 0 | AG40: 47415.96 | AI40: https://www.sitefotos.com/vpics/guestmapdev?v2o0r3 | AJ40: =W40*$C$3*$C$2/10^6 -> 8.237625 | AK40: Y | AL40: Medium/Strong | AM40: Lot is ~4x building footprint currently incl. parking; commercial + residential surrounding | AN40: 6 | AO40: =INDEX('Mireye Site Screen'!BU:BU, MATCH('Top 50'!$AN40, 'Mireye Site Screen'!$A:$A, 0)) -> REVIEW | AP40: =INDEX('Mireye Site Screen'!BV:BV, MATCH('Top 50'!$AN40, 'Mireye Site Screen'!$A:$A, 0)) -> Hold - verify Alliant service, assemblage, and Uniti lease terms; mid-tier
B41: Yes - High Rack count | C41: NCVLKYXA | D41: WNS1784 | E41: Owned | F41: Building | G41: Central Office | I41: 37.880671 | J41: -84.572366 | K41: 105 North York Street | L41: Nicholasville | M41: KY | N41: ON219-KY-035 | O41: 123 | P41: REIT_ILEC | Q41: Windstream Kentucky East| LLC | R41: ABS 1 | S41: 22704.46 | T41: 83234.99 | U41: 9764.05 | V41: 22830.17 | W41: 6190 | X41: 121 | Y41: 335 | Z41: 1385 | AA41: 1720 | AB41: 19185.03 | AC41: 26962.61 | AD41: 49596.69 | AE41: 46147.64 | AF41: 0 | AG41: 46147.64 | AI41: https://www.sitefotos.com/vpics/guestmapdev?e7q8w5 | AJ41: =W41*$C$3*$C$2/10^6 -> 1.160625
A42: Y | B42: Yes: 12k sqft + Owned | C42: NRFDOHXA | D42: WNS2297 | E42: Owned | F42: Building | G42: Central Office | I42: 41.314744 | J42: -81.537039 | K42: 54 Leonard Avenue | L42: Northfield | M42: OH | N42: B080033 | O42: 2701 | P42: REIT_ILEC | Q42: Windstream Western Reserve| Inc. | R42: ABS 1 | S42: 53064.32 | T42: 123417.05 | U42: 33189.06 | V42: 36876.69 | W42: 66721 | X42: 93 | Y42: 371 | Z42: 960 | AA42: 1331 | AB42: 4919.5 | AC42: 34006.75 | AD42: 24440.44 | AE42: 38926.25 | AF42: 0 | AG42: 38926.25 | AI42: https://www.sitefotos.com/vpics/guestmapdev?q4k0k6 | AJ42: =W42*$C$3*$C$2/10^6 -> 12.510188 | AK42: Y | AL42: Strong | AM42: Significant existing interior sq ft; significant lot space for expansion | AN42: 7 | AO42: =INDEX('Mireye Site Screen'!BU:BU, MATCH('Top 50'!$AN42, 'Mireye Site Screen'!$A:$A, 0)) -> REVIEW | AP42: =INDEX('Mireye Site Screen'!BV:BV, MATCH('Top 50'!$AN42, 'Mireye Site Screen'!$A:$A, 0)) -> Rises under operating-facility lens - verify serving utility (FirstEnergy?) + assemblage, then utility capacity inquiry on the 345 kV path
...

Sheet Mireye Site Screen
B1: Site | F1: Parcel (Regrid via Mireye) | M1: Power | Z1: Gas / BTM | AF1: Flood & Hazard | AQ1: Climate / Cooling | AU1: Air & Environment | BD1: Water / Sewer | BK1: Connectivity | BM1: Neighbors | BR1: Summary
A2: ID | B2: Site | C2: Lat | D2: Lng | E2: Screen depth | F2: Situs address | G2: Owner of record | H2: APN | I2: Zoning | J2: Parcel area (m2) | K2: Parcel area (acres) | L2: Parcel caveat | M2: ISO/RTO | N2: Serving utility (retail) | O2: Ind. elec price ($/kWh) | P2: Est. annual cost ($/MW-yr) | Q2: Substation dist (m) | R2: Substation max kV | S2: Trans line dist (m) | T2: Trans line kV | U2: Trans line owner | V2: Max kV within 10 km | W2: Substations in 10 km | X2: Redundancy flag | Y2: County queue (MW, generator-side) | Z2: Gas pipeline dist (m) | AA2: Interstate pipeline (m) | AB2: Ind. gas ($/MCF) | AC2: Grid ($/MWh) | AD2: Modeled gas gen ($/MWh, fuel-only) | AE2: BTM gas flag | AF2: FEMA zone | AG2: In SFHA | AH2: Seismic design cat. | AI2: PGA 2%/50yr (g) | AJ2: Design wind (mph) | AK2: Karst | AL2: Nearest dam (m) | AM2: Dam hazard class | AN2: High-hazard dams 10 km | AO2: Shrink-swell | AP2: Slope (deg) | AQ2: Design wet bulb (degC) | AR2: Days >=32C /yr | AS2: Free cooling h/yr @15C | AT2: Free cooling h/yr @10C | AU2: Ozone nonattainment | AV2: Worst class | AW2: Maintenance area | AX2: Superfund in 8 km | AY2: Brownfields in 8 km | AZ2: USTs in 1 km | BA2: Open LUST in 1 km | BB2: Opportunity Zone | BC2: Incentive stack | BD2: In water service area | BE2: Water system | BF2: System pop served | BG2: In sewer service area | BH2: Sewer provider | BI2: WWTP dist (m) | BJ2: WWTP pop served | BK2: FTTP providers | BL2: 5G class | BM2: Housing units 1 km | BN2: Density (units/km2) | BO2: Residential context | BP2: School dist (m) | BQ2: School name | BR2: Rank | BS2: Key strengths | BT2: Key risks | BU2: Verdict | BV2: Recommendation
